[2025-10-29 15:04:39,175: INFO: main]: Datascience package initialized.
[2025-10-29 16:05:29,305: ERROR: 2081104617]: name 'ConfigurationManager' is not defined
Traceback (most recent call last):
  File "C:\Users\amirhrst\AppData\Local\Temp\ipykernel_27020\2081104617.py", line 2, in <module>
    config = ConfigurationManager()
             ^^^^^^^^^^^^^^^^^^^^
NameError: name 'ConfigurationManager' is not defined
[2025-10-29 16:06:59,651: ERROR: 2081104617]: name 'read_yaml' is not defined
Traceback (most recent call last):
  File "C:\Users\amirhrst\AppData\Local\Temp\ipykernel_27020\2081104617.py", line 2, in <module>
    config = ConfigurationManager()
  File "C:\Users\amirhrst\AppData\Local\Temp\ipykernel_27020\1377879445.py", line 5, in __init__
    self.config = read_yaml(config_filepath)
                  ^^^^^^^^^
NameError: name 'read_yaml' is not defined
[2025-10-30 09:10:52,518: INFO: common]: YAML file: config\config.yaml loaded successfully
[2025-10-30 09:10:52,520: INFO: common]: YAML file: params.yaml loaded successfully
[2025-10-30 09:10:52,521: ERROR: common]: Error reading YAML file: params.yaml - First argument must be mapping or iterable
[2025-10-30 09:10:52,521: ERROR: 2081104617]: First argument must be mapping or iterable
Traceback (most recent call last):
  File "C:\Users\amirhrst\AppData\Local\Temp\ipykernel_13508\2081104617.py", line 2, in <module>
    config = ConfigurationManager()
  File "C:\Users\amirhrst\AppData\Local\Temp\ipykernel_13508\1377879445.py", line 6, in __init__
    self.params = read_yaml(params_filepath)
                  ~~~~~~~~~^^^^^^^^^^^^^^^^^
  File "d:\Projects\dsproject\.venv\Lib\site-packages\ensure\main.py", line 872, in __call__
    return_val = self.f(*args, **kwargs)
  File "d:\Projects\dsproject\src\datascience\utils\common.py", line 29, in read_yaml
    raise e
  File "d:\Projects\dsproject\src\datascience\utils\common.py", line 26, in read_yaml
    return ConfigBox(content)
  File "box\\box.py", line 295, in box.box.Box.__init__
box.exceptions.BoxValueError: First argument must be mapping or iterable
[2025-10-30 09:14:27,738: INFO: common]: YAML file: config\config.yaml loaded successfully
[2025-10-30 09:14:27,741: INFO: common]: YAML file: params.yaml loaded successfully
[2025-10-30 09:14:27,742: INFO: common]: YAML file: schema.yaml loaded successfully
[2025-10-30 09:14:27,743: ERROR: 2081104617]: "'ConfigBox' object has no attribute 'artifacts_root'"
Traceback (most recent call last):
  File "box\\box.py", line 594, in box.box.Box.__getitem__
KeyError: 'artifacts_root'

The above exception was the direct cause of the following exception:

Traceback (most recent call last):
  File "box\\box.py", line 633, in box.box.Box.__getattr__
  File "box\\box.py", line 621, in box.box.Box.__getitem__
box.exceptions.BoxKeyError: "'artifacts_root'"

During handling of the above exception, another exception occurred:

Traceback (most recent call last):
  File "box\\box.py", line 635, in box.box.Box.__getattr__
AttributeError: 'ConfigBox' object has no attribute 'artifacts_root'

The above exception was the direct cause of the following exception:

Traceback (most recent call last):
  File "box\\config_box.py", line 29, in box.config_box.ConfigBox.__getattr__
  File "box\\box.py", line 649, in box.box.Box.__getattr__
box.exceptions.BoxKeyError: "'ConfigBox' object has no attribute 'artifacts_root'"

During handling of the above exception, another exception occurred:

Traceback (most recent call last):
  File "box\\box.py", line 594, in box.box.Box.__getitem__
KeyError: 'artifacts_root'

The above exception was the direct cause of the following exception:

Traceback (most recent call last):
  File "box\\box.py", line 633, in box.box.Box.__getattr__
  File "box\\box.py", line 621, in box.box.Box.__getitem__
box.exceptions.BoxKeyError: "'artifacts_root'"

During handling of the above exception, another exception occurred:

Traceback (most recent call last):
  File "box\\box.py", line 635, in box.box.Box.__getattr__
AttributeError: 'ConfigBox' object has no attribute 'artifacts_root'

The above exception was the direct cause of the following exception:

Traceback (most recent call last):
  File "C:\Users\amirhrst\AppData\Local\Temp\ipykernel_13508\2081104617.py", line 2, in <module>
    config = ConfigurationManager()
  File "C:\Users\amirhrst\AppData\Local\Temp\ipykernel_13508\1377879445.py", line 9, in __init__
    create_directories([self.config.artifacts_root])
                        ^^^^^^^^^^^^^^^^^^^^^^^^^^
  File "box\\config_box.py", line 31, in box.config_box.ConfigBox.__getattr__
  File "box\\box.py", line 649, in box.box.Box.__getattr__
box.exceptions.BoxKeyError: "'ConfigBox' object has no attribute 'artifacts_root'"
[2025-10-30 09:16:19,635: INFO: common]: YAML file: config\config.yaml loaded successfully
[2025-10-30 09:16:19,637: INFO: common]: YAML file: params.yaml loaded successfully
[2025-10-30 09:16:19,638: INFO: common]: YAML file: schema.yaml loaded successfully
[2025-10-30 09:16:19,639: INFO: common]: Directory created at: artifacts
[2025-10-30 09:16:19,640: ERROR: 2081104617]: isinstance() arg 2 must be a type, a tuple of types, or a union
Traceback (most recent call last):
  File "C:\Users\amirhrst\AppData\Local\Temp\ipykernel_13508\2081104617.py", line 2, in <module>
    config = ConfigurationManager()
  File "C:\Users\amirhrst\AppData\Local\Temp\ipykernel_13508\1377879445.py", line 9, in __init__
    create_directories([self.config.artifacts_root])
    ~~~~~~~~~~~~~~~~~~^^^^^^^^^^^^^^^^^^^^^^^^^^^^^^
  File "d:\Projects\dsproject\.venv\Lib\site-packages\ensure\main.py", line 873, in __call__
    if not isinstance(return_val, self.return_templ):
           ~~~~~~~~~~^^^^^^^^^^^^^^^^^^^^^^^^^^^^^^^
TypeError: isinstance() arg 2 must be a type, a tuple of types, or a union
[2025-10-30 09:17:54,750: INFO: common]: YAML file: config\config.yaml loaded successfully
[2025-10-30 09:17:54,751: INFO: common]: YAML file: params.yaml loaded successfully
[2025-10-30 09:17:54,752: INFO: common]: YAML file: schema.yaml loaded successfully
[2025-10-30 09:17:54,753: INFO: common]: Directory created at: artifacts
[2025-10-30 09:17:54,753: ERROR: 2081104617]: isinstance() arg 2 must be a type, a tuple of types, or a union
Traceback (most recent call last):
  File "C:\Users\amirhrst\AppData\Local\Temp\ipykernel_13508\2081104617.py", line 2, in <module>
    config = ConfigurationManager()
  File "C:\Users\amirhrst\AppData\Local\Temp\ipykernel_13508\1377879445.py", line 9, in __init__
    create_directories([self.config.artifacts_root])
    ~~~~~~~~~~~~~~~~~~^^^^^^^^^^^^^^^^^^^^^^^^^^^^^^
  File "d:\Projects\dsproject\.venv\Lib\site-packages\ensure\main.py", line 873, in __call__
    if not isinstance(return_val, self.return_templ):
           ~~~~~~~~~~^^^^^^^^^^^^^^^^^^^^^^^^^^^^^^^
TypeError: isinstance() arg 2 must be a type, a tuple of types, or a union
[2025-10-30 09:20:49,645: INFO: common]: YAML file: config\config.yaml loaded successfully
[2025-10-30 09:20:49,646: INFO: common]: YAML file: params.yaml loaded successfully
[2025-10-30 09:20:49,647: INFO: common]: YAML file: schema.yaml loaded successfully
[2025-10-30 09:20:49,648: INFO: common]: Directory created at: artifacts
[2025-10-30 09:20:49,648: ERROR: 2081104617]: isinstance() arg 2 must be a type, a tuple of types, or a union
Traceback (most recent call last):
  File "C:\Users\amirhrst\AppData\Local\Temp\ipykernel_13508\2081104617.py", line 2, in <module>
    config = ConfigurationManager()
  File "C:\Users\amirhrst\AppData\Local\Temp\ipykernel_13508\1377879445.py", line 9, in __init__
    create_directories([self.config.artifacts_root])
    ~~~~~~~~~~~~~~~~~~^^^^^^^^^^^^^^^^^^^^^^^^^^^^^^
  File "d:\Projects\dsproject\.venv\Lib\site-packages\ensure\main.py", line 873, in __call__
    if not isinstance(return_val, self.return_templ):
           ~~~~~~~~~~^^^^^^^^^^^^^^^^^^^^^^^^^^^^^^^
TypeError: isinstance() arg 2 must be a type, a tuple of types, or a union
[2025-10-30 09:21:04,010: INFO: common]: YAML file: config\config.yaml loaded successfully
[2025-10-30 09:21:04,011: INFO: common]: YAML file: params.yaml loaded successfully
[2025-10-30 09:21:04,012: INFO: common]: YAML file: schema.yaml loaded successfully
[2025-10-30 09:21:04,012: INFO: common]: Directory created at: artifacts
[2025-10-30 09:21:04,013: ERROR: 2081104617]: isinstance() arg 2 must be a type, a tuple of types, or a union
Traceback (most recent call last):
  File "C:\Users\amirhrst\AppData\Local\Temp\ipykernel_13508\2081104617.py", line 2, in <module>
    config = ConfigurationManager()
  File "C:\Users\amirhrst\AppData\Local\Temp\ipykernel_13508\1377879445.py", line 9, in __init__
    create_directories([self.config.artifacts_root])
    ~~~~~~~~~~~~~~~~~~^^^^^^^^^^^^^^^^^^^^^^^^^^^^^^
  File "d:\Projects\dsproject\.venv\Lib\site-packages\ensure\main.py", line 873, in __call__
    if not isinstance(return_val, self.return_templ):
           ~~~~~~~~~~^^^^^^^^^^^^^^^^^^^^^^^^^^^^^^^
TypeError: isinstance() arg 2 must be a type, a tuple of types, or a union
[2025-10-30 09:25:49,901: INFO: common]: YAML file: config\config.yaml loaded successfully
[2025-10-30 09:25:49,902: INFO: common]: YAML file: params.yaml loaded successfully
[2025-10-30 09:25:49,903: INFO: common]: YAML file: schema.yaml loaded successfully
[2025-10-30 09:25:49,903: INFO: common]: Directory created at: artifacts
[2025-10-30 09:25:49,904: ERROR: 2081104617]: isinstance() arg 2 must be a type, a tuple of types, or a union
Traceback (most recent call last):
  File "C:\Users\amirhrst\AppData\Local\Temp\ipykernel_13508\2081104617.py", line 2, in <module>
    config = ConfigurationManager()
  File "C:\Users\amirhrst\AppData\Local\Temp\ipykernel_13508\1377879445.py", line 9, in __init__
    create_directories([self.config.artifacts_root])
    ~~~~~~~~~~~~~~~~~~^^^^^^^^^^^^^^^^^^^^^^^^^^^^^^
  File "d:\Projects\dsproject\.venv\Lib\site-packages\ensure\main.py", line 873, in __call__
    if not isinstance(return_val, self.return_templ):
           ~~~~~~~~~~^^^^^^^^^^^^^^^^^^^^^^^^^^^^^^^
TypeError: isinstance() arg 2 must be a type, a tuple of types, or a union
[2025-10-30 09:26:16,765: INFO: common]: YAML file: config\config.yaml loaded successfully
[2025-10-30 09:26:16,766: INFO: common]: YAML file: params.yaml loaded successfully
[2025-10-30 09:26:16,767: INFO: common]: YAML file: schema.yaml loaded successfully
[2025-10-30 09:26:16,768: INFO: common]: created directory at: artifacts
[2025-10-30 09:26:16,768: INFO: common]: created directory at: artifacts/data_ingestion
[2025-10-30 09:26:17,414: INFO: 1026146470]: Downloading data from https://github.com/krishnaik06/datasets/raw/refs/heads/main/winequality-data.zip to artifacts/data_ingestion/data.zip
[2025-10-30 09:26:17,415: INFO: 1026146470]: Download completed.
[2025-10-30 09:26:17,430: INFO: 1026146470]: Extracted zip file artifacts/data_ingestion/data.zip to artifacts/data_ingestion
[2025-10-30 09:47:44,494: INFO: main]: Datascience package initialized.
[2025-10-30 09:49:23,398: INFO: main]: Datascience package initialized.
[2025-10-30 09:49:40,631: INFO: main]: Datascience package initialized.
[2025-10-30 09:50:27,021: INFO: main]: Datascience package initialized.
[2025-10-30 09:51:08,302: INFO: main]: Datascience package initialized.
[2025-10-30 09:51:29,115: INFO: main]: Datascience package initialized.
[2025-10-30 09:51:48,603: INFO: main]: Datascience package initialized.
[2025-10-30 09:51:49,619: INFO: main]: >>>>>> Stage Data Ingestion Stage started <<<<<<
[2025-10-30 09:51:49,621: INFO: common]: YAML file: config\config.yaml loaded successfully
[2025-10-30 09:51:49,622: INFO: common]: YAML file: params.yaml loaded successfully
[2025-10-30 09:51:49,623: INFO: common]: YAML file: schema.yaml loaded successfully
[2025-10-30 09:51:49,624: INFO: common]: created directory at: artifacts
[2025-10-30 09:51:49,624: INFO: common]: created directory at: artifacts/data_ingestion
[2025-10-30 09:51:49,634: INFO: data_ingestion]: Extracted zip file artifacts/data_ingestion/data.zip to artifacts/data_ingestion
[2025-10-30 09:51:49,634: INFO: main]: >>>>>> Stage Data Ingestion Stage completed <<<<<<


[2025-10-30 10:22:48,020: INFO: common]: YAML file: config\config.yaml loaded successfully
[2025-10-30 10:22:48,022: INFO: common]: YAML file: params.yaml loaded successfully
[2025-10-30 10:22:48,024: INFO: common]: YAML file: schema.yaml loaded successfully
[2025-10-30 10:22:48,025: INFO: common]: created directory at: artifacts
[2025-10-30 10:22:48,026: INFO: common]: created directory at: artifacts/data_validation
[2025-10-30 10:51:56,792: INFO: main]: Datascience package initialized.
[2025-10-30 10:52:03,882: INFO: main]: Datascience package initialized.
[2025-10-30 10:53:57,909: INFO: main]: Datascience package initialized.
[2025-10-30 10:53:58,396: INFO: main]: >>>>>> Stage Data Ingestion Stage started <<<<<<
[2025-10-30 10:53:58,398: INFO: common]: YAML file: config\config.yaml loaded successfully
[2025-10-30 10:53:58,399: INFO: common]: YAML file: params.yaml loaded successfully
[2025-10-30 10:53:58,400: INFO: common]: YAML file: schema.yaml loaded successfully
[2025-10-30 10:53:58,400: INFO: common]: created directory at: artifacts
[2025-10-30 10:53:58,400: INFO: common]: created directory at: artifacts/data_ingestion
[2025-10-30 10:53:58,402: INFO: data_ingestion]: Extracted zip file artifacts/data_ingestion/data.zip to artifacts/data_ingestion
[2025-10-30 10:53:58,402: INFO: main]: >>>>>> Stage Data Ingestion Stage completed <<<<<<


[2025-10-30 10:53:58,403: INFO: main]: >>>>>> Stage Data Validation Stage started <<<<<<
[2025-10-30 10:53:58,404: INFO: common]: YAML file: config\config.yaml loaded successfully
[2025-10-30 10:53:58,404: INFO: common]: YAML file: params.yaml loaded successfully
[2025-10-30 10:53:58,405: INFO: common]: YAML file: schema.yaml loaded successfully
[2025-10-30 10:53:58,406: INFO: common]: created directory at: artifacts
[2025-10-30 10:53:58,406: ERROR: main]: 'ConfigurationManager' object has no attribute 'get_data_validation_config'
Traceback (most recent call last):
  File "D:\Projects\dsproject\main.py", line 24, in <module>
    data_validation.main()
    ~~~~~~~~~~~~~~~~~~~~^^
  File "D:\Projects\dsproject\src\datascience\pipeline\data_validation_pipline.py", line 13, in main
    data_validation_config = config.get_data_validation_config()
                             ^^^^^^^^^^^^^^^^^^^^^^^^^^^^^^^^^
AttributeError: 'ConfigurationManager' object has no attribute 'get_data_validation_config'. Did you mean: 'get_data_ingestion_config'?
[2025-10-30 10:56:28,602: INFO: main]: Datascience package initialized.
[2025-10-30 10:56:29,053: INFO: main]: >>>>>> Stage Data Ingestion Stage started <<<<<<
[2025-10-30 10:56:29,054: INFO: common]: YAML file: config\config.yaml loaded successfully
[2025-10-30 10:56:29,055: INFO: common]: YAML file: params.yaml loaded successfully
[2025-10-30 10:56:29,056: INFO: common]: YAML file: schema.yaml loaded successfully
[2025-10-30 10:56:29,056: INFO: common]: created directory at: artifacts
[2025-10-30 10:56:29,057: INFO: common]: created directory at: artifacts/data_ingestion
[2025-10-30 10:56:29,058: INFO: data_ingestion]: Extracted zip file artifacts/data_ingestion/data.zip to artifacts/data_ingestion
[2025-10-30 10:56:29,059: INFO: main]: >>>>>> Stage Data Ingestion Stage completed <<<<<<


[2025-10-30 10:56:29,059: INFO: main]: >>>>>> Stage Data Validation Stage started <<<<<<
[2025-10-30 10:56:29,060: INFO: common]: YAML file: config\config.yaml loaded successfully
[2025-10-30 10:56:29,061: INFO: common]: YAML file: params.yaml loaded successfully
[2025-10-30 10:56:29,062: INFO: common]: YAML file: schema.yaml loaded successfully
[2025-10-30 10:56:29,062: INFO: common]: created directory at: artifacts
[2025-10-30 10:56:29,062: INFO: common]: created directory at: artifacts/data_validation
[2025-10-30 10:56:29,080: INFO: data_validation_pipline]: Data validation status: False
[2025-10-30 10:56:29,080: INFO: main]: >>>>>> Stage Data Validation Stage completed <<<<<<


[2025-10-30 11:32:45,239: INFO: main]: Datascience package initialized.
[2025-10-30 11:33:21,896: INFO: main]: Datascience package initialized.
[2025-10-30 11:33:22,972: INFO: main]: >>>>>> Stage Data Ingestion Stage started <<<<<<
[2025-10-30 11:33:22,973: INFO: common]: YAML file: config\config.yaml loaded successfully
[2025-10-30 11:33:22,974: INFO: common]: YAML file: params.yaml loaded successfully
[2025-10-30 11:33:22,975: INFO: common]: YAML file: schema.yaml loaded successfully
[2025-10-30 11:33:22,975: INFO: common]: created directory at: artifacts
[2025-10-30 11:33:22,975: INFO: common]: created directory at: artifacts/data_ingestion
[2025-10-30 11:33:22,977: INFO: data_ingestion]: Extracted zip file artifacts/data_ingestion/data.zip to artifacts/data_ingestion
[2025-10-30 11:33:22,977: INFO: main]: >>>>>> Stage Data Ingestion Stage completed <<<<<<


[2025-10-30 11:33:22,978: INFO: main]: >>>>>> Stage Data Validation Stage started <<<<<<
[2025-10-30 11:33:22,979: INFO: common]: YAML file: config\config.yaml loaded successfully
[2025-10-30 11:33:22,980: INFO: common]: YAML file: params.yaml loaded successfully
[2025-10-30 11:33:22,981: INFO: common]: YAML file: schema.yaml loaded successfully
[2025-10-30 11:33:22,981: INFO: common]: created directory at: artifacts
[2025-10-30 11:33:22,981: INFO: common]: created directory at: artifacts/data_validation
[2025-10-30 11:33:22,998: INFO: data_validation_pipline]: Data validation status: False
[2025-10-30 11:33:22,998: INFO: main]: >>>>>> Stage Data Validation Stage completed <<<<<<


[2025-10-30 11:33:22,999: INFO: main]: >>>>>> Stage Data Transformation Stage started <<<<<<
[2025-10-30 11:33:23,006: ERROR: data_transformation_pipline]: Your Data scheme is not valid
Traceback (most recent call last):
  File "D:\Projects\dsproject\src\datascience\pipeline\data_transformation_pipline.py", line 30, in initiate_data_transformation
    raise Exception("Your Data scheme is not valid")
Exception: Your Data scheme is not valid
[2025-10-30 11:33:23,007: ERROR: main]: Your Data scheme is not valid
Traceback (most recent call last):
  File "D:\Projects\dsproject\main.py", line 34, in <module>
    data_transformation.initiate_data_transformation()
    ~~~~~~~~~~~~~~~~~~~~~~~~~~~~~~~~~~~~~~~~~~~~~~~~^^
  File "D:\Projects\dsproject\src\datascience\pipeline\data_transformation_pipline.py", line 33, in initiate_data_transformation
    raise e
  File "D:\Projects\dsproject\src\datascience\pipeline\data_transformation_pipline.py", line 30, in initiate_data_transformation
    raise Exception("Your Data scheme is not valid")
Exception: Your Data scheme is not valid
[2025-10-30 11:34:09,431: INFO: main]: Datascience package initialized.
[2025-10-30 11:34:10,442: INFO: main]: >>>>>> Stage Data Ingestion Stage started <<<<<<
[2025-10-30 11:34:10,444: INFO: common]: YAML file: config\config.yaml loaded successfully
[2025-10-30 11:34:10,444: INFO: common]: YAML file: params.yaml loaded successfully
[2025-10-30 11:34:10,445: INFO: common]: YAML file: schema.yaml loaded successfully
[2025-10-30 11:34:10,446: INFO: common]: created directory at: artifacts
[2025-10-30 11:34:10,446: INFO: common]: created directory at: artifacts/data_ingestion
[2025-10-30 11:34:10,448: INFO: data_ingestion]: Extracted zip file artifacts/data_ingestion/data.zip to artifacts/data_ingestion
[2025-10-30 11:34:10,448: INFO: main]: >>>>>> Stage Data Ingestion Stage completed <<<<<<


[2025-10-30 11:34:10,448: INFO: main]: >>>>>> Stage Data Validation Stage started <<<<<<
[2025-10-30 11:34:10,449: INFO: common]: YAML file: config\config.yaml loaded successfully
[2025-10-30 11:34:10,450: INFO: common]: YAML file: params.yaml loaded successfully
[2025-10-30 11:34:10,451: INFO: common]: YAML file: schema.yaml loaded successfully
[2025-10-30 11:34:10,451: INFO: common]: created directory at: artifacts
[2025-10-30 11:34:10,451: INFO: common]: created directory at: artifacts/data_validation
[2025-10-30 11:34:10,466: INFO: data_validation_pipline]: Data validation status: False
[2025-10-30 11:34:10,467: INFO: main]: >>>>>> Stage Data Validation Stage completed <<<<<<


[2025-10-30 11:34:10,467: INFO: main]: >>>>>> Stage Data Transformation Stage started <<<<<<
[2025-10-30 11:34:10,468: ERROR: data_transformation_pipline]: Your Data scheme is not valid
Traceback (most recent call last):
  File "D:\Projects\dsproject\src\datascience\pipeline\data_transformation_pipline.py", line 30, in initiate_data_transformation
    raise Exception("Your Data scheme is not valid")
Exception: Your Data scheme is not valid
[2025-10-30 11:34:10,469: ERROR: main]: Your Data scheme is not valid
Traceback (most recent call last):
  File "D:\Projects\dsproject\main.py", line 34, in <module>
    data_transformation.initiate_data_transformation()
    ~~~~~~~~~~~~~~~~~~~~~~~~~~~~~~~~~~~~~~~~~~~~~~~~^^
  File "D:\Projects\dsproject\src\datascience\pipeline\data_transformation_pipline.py", line 33, in initiate_data_transformation
    raise e
  File "D:\Projects\dsproject\src\datascience\pipeline\data_transformation_pipline.py", line 30, in initiate_data_transformation
    raise Exception("Your Data scheme is not valid")
Exception: Your Data scheme is not valid
[2025-10-30 11:34:28,912: INFO: main]: Datascience package initialized.
[2025-10-30 11:34:29,923: INFO: main]: >>>>>> Stage Data Ingestion Stage started <<<<<<
[2025-10-30 11:34:29,925: INFO: common]: YAML file: config\config.yaml loaded successfully
[2025-10-30 11:34:29,925: INFO: common]: YAML file: params.yaml loaded successfully
[2025-10-30 11:34:29,926: INFO: common]: YAML file: schema.yaml loaded successfully
[2025-10-30 11:34:29,927: INFO: common]: created directory at: artifacts
[2025-10-30 11:34:29,927: INFO: common]: created directory at: artifacts/data_ingestion
[2025-10-30 11:34:29,928: INFO: data_ingestion]: Extracted zip file artifacts/data_ingestion/data.zip to artifacts/data_ingestion
[2025-10-30 11:34:29,929: INFO: main]: >>>>>> Stage Data Ingestion Stage completed <<<<<<


[2025-10-30 11:34:29,929: INFO: main]: >>>>>> Stage Data Validation Stage started <<<<<<
[2025-10-30 11:34:29,930: INFO: common]: YAML file: config\config.yaml loaded successfully
[2025-10-30 11:34:29,930: INFO: common]: YAML file: params.yaml loaded successfully
[2025-10-30 11:34:29,931: INFO: common]: YAML file: schema.yaml loaded successfully
[2025-10-30 11:34:29,932: INFO: common]: created directory at: artifacts
[2025-10-30 11:34:29,932: INFO: common]: created directory at: artifacts/data_validation
[2025-10-30 11:34:29,948: INFO: data_validation_pipline]: Data validation status: False
[2025-10-30 11:34:29,948: INFO: main]: >>>>>> Stage Data Validation Stage completed <<<<<<


[2025-10-30 11:34:29,948: INFO: main]: >>>>>> Stage Data Transformation Stage started <<<<<<
[2025-10-30 11:34:29,949: ERROR: data_transformation_pipline]: Your Data scheme is not valid
Traceback (most recent call last):
  File "D:\Projects\dsproject\src\datascience\pipeline\data_transformation_pipline.py", line 30, in initiate_data_transformation
    raise Exception("Your Data scheme is not valid")
Exception: Your Data scheme is not valid
[2025-10-30 11:34:29,950: ERROR: main]: Your Data scheme is not valid
Traceback (most recent call last):
  File "D:\Projects\dsproject\main.py", line 34, in <module>
    data_transformation.initiate_data_transformation()
    ~~~~~~~~~~~~~~~~~~~~~~~~~~~~~~~~~~~~~~~~~~~~~~~~^^
  File "D:\Projects\dsproject\src\datascience\pipeline\data_transformation_pipline.py", line 33, in initiate_data_transformation
    raise e
  File "D:\Projects\dsproject\src\datascience\pipeline\data_transformation_pipline.py", line 30, in initiate_data_transformation
    raise Exception("Your Data scheme is not valid")
Exception: Your Data scheme is not valid
[2025-10-30 11:37:14,843: INFO: main]: Datascience package initialized.
[2025-10-30 11:37:15,921: INFO: main]: >>>>>> Stage Data Ingestion Stage started <<<<<<
[2025-10-30 11:37:15,923: INFO: common]: YAML file: config\config.yaml loaded successfully
[2025-10-30 11:37:15,924: INFO: common]: YAML file: params.yaml loaded successfully
[2025-10-30 11:37:15,925: INFO: common]: YAML file: schema.yaml loaded successfully
[2025-10-30 11:37:15,926: INFO: common]: created directory at: artifacts
[2025-10-30 11:37:15,926: INFO: common]: created directory at: artifacts/data_ingestion
[2025-10-30 11:37:15,928: INFO: data_ingestion]: Extracted zip file artifacts/data_ingestion/data.zip to artifacts/data_ingestion
[2025-10-30 11:37:15,928: INFO: main]: >>>>>> Stage Data Ingestion Stage completed <<<<<<


[2025-10-30 11:37:15,928: INFO: main]: >>>>>> Stage Data Validation Stage started <<<<<<
[2025-10-30 11:37:15,929: INFO: common]: YAML file: config\config.yaml loaded successfully
[2025-10-30 11:37:15,930: INFO: common]: YAML file: params.yaml loaded successfully
[2025-10-30 11:37:15,931: INFO: common]: YAML file: schema.yaml loaded successfully
[2025-10-30 11:37:15,931: INFO: common]: created directory at: artifacts
[2025-10-30 11:37:15,931: INFO: common]: created directory at: artifacts/data_validation
[2025-10-30 11:37:15,946: INFO: data_validation_pipline]: Data validation status: False
[2025-10-30 11:37:15,946: INFO: main]: >>>>>> Stage Data Validation Stage completed <<<<<<


[2025-10-30 11:37:15,947: INFO: main]: >>>>>> Stage Data Transformation Stage started <<<<<<
[2025-10-30 11:37:15,948: ERROR: data_transformation_pipline]: Your Data scheme is not valid
Traceback (most recent call last):
  File "D:\Projects\dsproject\src\datascience\pipeline\data_transformation_pipline.py", line 30, in initiate_data_transformation
    raise Exception("Your Data scheme is not valid")
Exception: Your Data scheme is not valid
[2025-10-30 11:37:15,948: ERROR: main]: Your Data scheme is not valid
Traceback (most recent call last):
  File "D:\Projects\dsproject\main.py", line 34, in <module>
    data_transformation.initiate_data_transformation()
    ~~~~~~~~~~~~~~~~~~~~~~~~~~~~~~~~~~~~~~~~~~~~~~~~^^
  File "D:\Projects\dsproject\src\datascience\pipeline\data_transformation_pipline.py", line 33, in initiate_data_transformation
    raise e
  File "D:\Projects\dsproject\src\datascience\pipeline\data_transformation_pipline.py", line 30, in initiate_data_transformation
    raise Exception("Your Data scheme is not valid")
Exception: Your Data scheme is not valid
[2025-10-30 11:40:58,502: INFO: main]: Datascience package initialized.
[2025-10-30 11:40:59,553: INFO: main]: >>>>>> Stage Data Ingestion Stage started <<<<<<
[2025-10-30 11:40:59,555: INFO: common]: YAML file: config\config.yaml loaded successfully
[2025-10-30 11:40:59,556: INFO: common]: YAML file: params.yaml loaded successfully
[2025-10-30 11:40:59,557: INFO: common]: YAML file: schema.yaml loaded successfully
[2025-10-30 11:40:59,558: INFO: common]: created directory at: artifacts
[2025-10-30 11:40:59,558: INFO: common]: created directory at: artifacts/data_ingestion
[2025-10-30 11:40:59,560: INFO: data_ingestion]: Extracted zip file artifacts/data_ingestion/data.zip to artifacts/data_ingestion
[2025-10-30 11:40:59,560: INFO: main]: >>>>>> Stage Data Ingestion Stage completed <<<<<<


[2025-10-30 11:40:59,560: INFO: main]: >>>>>> Stage Data Validation Stage started <<<<<<
[2025-10-30 11:40:59,562: INFO: common]: YAML file: config\config.yaml loaded successfully
[2025-10-30 11:40:59,562: INFO: common]: YAML file: params.yaml loaded successfully
[2025-10-30 11:40:59,563: INFO: common]: YAML file: schema.yaml loaded successfully
[2025-10-30 11:40:59,563: INFO: common]: created directory at: artifacts
[2025-10-30 11:40:59,563: INFO: common]: created directory at: artifacts/data_validation
[2025-10-30 11:40:59,580: INFO: data_validation_pipline]: Data validation status: False
[2025-10-30 11:40:59,580: INFO: main]: >>>>>> Stage Data Validation Stage completed <<<<<<


[2025-10-30 11:40:59,580: INFO: main]: >>>>>> Stage Data Transformation Stage started <<<<<<
[2025-10-30 11:40:59,581: ERROR: data_transformation_pipline]: Your Data scheme is not valid
Traceback (most recent call last):
  File "D:\Projects\dsproject\src\datascience\pipeline\data_transformation_pipline.py", line 30, in initiate_data_transformation
    raise Exception("Your Data scheme is not valid")
Exception: Your Data scheme is not valid
[2025-10-30 11:40:59,582: ERROR: main]: Your Data scheme is not valid
Traceback (most recent call last):
  File "D:\Projects\dsproject\main.py", line 34, in <module>
    data_transformation.initiate_data_transformation()
    ~~~~~~~~~~~~~~~~~~~~~~~~~~~~~~~~~~~~~~~~~~~~~~~~^^
  File "D:\Projects\dsproject\src\datascience\pipeline\data_transformation_pipline.py", line 33, in initiate_data_transformation
    raise e
  File "D:\Projects\dsproject\src\datascience\pipeline\data_transformation_pipline.py", line 30, in initiate_data_transformation
    raise Exception("Your Data scheme is not valid")
Exception: Your Data scheme is not valid
[2025-10-30 11:45:14,932: INFO: main]: Datascience package initialized.
[2025-10-30 11:45:15,918: INFO: main]: >>>>>> Stage Data Ingestion Stage started <<<<<<
[2025-10-30 11:45:15,920: INFO: common]: YAML file: config\config.yaml loaded successfully
[2025-10-30 11:45:15,920: INFO: common]: YAML file: params.yaml loaded successfully
[2025-10-30 11:45:15,921: INFO: common]: YAML file: schema.yaml loaded successfully
[2025-10-30 11:45:15,922: INFO: common]: created directory at: artifacts
[2025-10-30 11:45:15,922: INFO: common]: created directory at: artifacts/data_ingestion
[2025-10-30 11:45:15,924: INFO: data_ingestion]: Extracted zip file artifacts/data_ingestion/data.zip to artifacts/data_ingestion
[2025-10-30 11:45:15,924: INFO: main]: >>>>>> Stage Data Ingestion Stage completed <<<<<<


[2025-10-30 11:45:15,924: INFO: main]: >>>>>> Stage Data Validation Stage started <<<<<<
[2025-10-30 11:45:15,925: INFO: common]: YAML file: config\config.yaml loaded successfully
[2025-10-30 11:45:15,926: INFO: common]: YAML file: params.yaml loaded successfully
[2025-10-30 11:45:15,927: INFO: common]: YAML file: schema.yaml loaded successfully
[2025-10-30 11:45:15,927: INFO: common]: created directory at: artifacts
[2025-10-30 11:45:15,927: INFO: common]: created directory at: artifacts/data_validation
[2025-10-30 11:45:15,943: INFO: data_validation_pipline]: Data validation status: False
[2025-10-30 11:45:15,943: INFO: main]: >>>>>> Stage Data Validation Stage completed <<<<<<


[2025-10-30 11:45:15,943: INFO: main]: >>>>>> Stage Data Transformation Stage started <<<<<<
[2025-10-30 11:45:15,944: ERROR: data_transformation_pipline]: Your Data scheme is not valid
Traceback (most recent call last):
  File "D:\Projects\dsproject\src\datascience\pipeline\data_transformation_pipline.py", line 30, in initiate_data_transformation
    raise Exception("Your Data scheme is not valid")
Exception: Your Data scheme is not valid
[2025-10-30 11:45:15,945: ERROR: main]: Your Data scheme is not valid
Traceback (most recent call last):
  File "D:\Projects\dsproject\main.py", line 34, in <module>
    data_transformation.initiate_data_transformation()
    ~~~~~~~~~~~~~~~~~~~~~~~~~~~~~~~~~~~~~~~~~~~~~~~~^^
  File "D:\Projects\dsproject\src\datascience\pipeline\data_transformation_pipline.py", line 33, in initiate_data_transformation
    raise e
  File "D:\Projects\dsproject\src\datascience\pipeline\data_transformation_pipline.py", line 30, in initiate_data_transformation
    raise Exception("Your Data scheme is not valid")
Exception: Your Data scheme is not valid
[2025-10-30 11:46:18,578: INFO: main]: Datascience package initialized.
[2025-10-30 11:46:19,555: INFO: main]: >>>>>> Stage Data Ingestion Stage started <<<<<<
[2025-10-30 11:46:19,557: INFO: common]: YAML file: config\config.yaml loaded successfully
[2025-10-30 11:46:19,557: INFO: common]: YAML file: params.yaml loaded successfully
[2025-10-30 11:46:19,558: INFO: common]: YAML file: schema.yaml loaded successfully
[2025-10-30 11:46:19,559: INFO: common]: created directory at: artifacts
[2025-10-30 11:46:19,559: INFO: common]: created directory at: artifacts/data_ingestion
[2025-10-30 11:46:19,561: INFO: data_ingestion]: Extracted zip file artifacts/data_ingestion/data.zip to artifacts/data_ingestion
[2025-10-30 11:46:19,561: INFO: main]: >>>>>> Stage Data Ingestion Stage completed <<<<<<


[2025-10-30 11:46:19,561: INFO: main]: >>>>>> Stage Data Validation Stage started <<<<<<
[2025-10-30 11:46:19,563: INFO: common]: YAML file: config\config.yaml loaded successfully
[2025-10-30 11:46:19,563: INFO: common]: YAML file: params.yaml loaded successfully
[2025-10-30 11:46:19,564: INFO: common]: YAML file: schema.yaml loaded successfully
[2025-10-30 11:46:19,564: INFO: common]: created directory at: artifacts
[2025-10-30 11:46:19,565: INFO: common]: created directory at: artifacts/data_validation
[2025-10-30 11:46:19,579: INFO: data_validation_pipline]: Data validation status: False
[2025-10-30 11:46:19,580: INFO: main]: >>>>>> Stage Data Validation Stage completed <<<<<<


[2025-10-30 11:46:19,580: INFO: main]: >>>>>> Stage Data Transformation Stage started <<<<<<
[2025-10-30 11:46:19,581: ERROR: data_transformation_pipline]: Your Data scheme is not valid
Traceback (most recent call last):
  File "D:\Projects\dsproject\src\datascience\pipeline\data_transformation_pipline.py", line 30, in initiate_data_transformation
    raise Exception("Your Data scheme is not valid")
Exception: Your Data scheme is not valid
[2025-10-30 11:46:19,582: ERROR: main]: Your Data scheme is not valid
Traceback (most recent call last):
  File "D:\Projects\dsproject\main.py", line 34, in <module>
    data_transformation.initiate_data_transformation()
    ~~~~~~~~~~~~~~~~~~~~~~~~~~~~~~~~~~~~~~~~~~~~~~~~^^
  File "D:\Projects\dsproject\src\datascience\pipeline\data_transformation_pipline.py", line 33, in initiate_data_transformation
    raise e
  File "D:\Projects\dsproject\src\datascience\pipeline\data_transformation_pipline.py", line 30, in initiate_data_transformation
    raise Exception("Your Data scheme is not valid")
Exception: Your Data scheme is not valid
[2025-10-30 11:47:23,230: INFO: main]: Datascience package initialized.
[2025-10-30 11:47:24,212: INFO: main]: >>>>>> Stage Data Ingestion Stage started <<<<<<
[2025-10-30 11:47:24,213: INFO: common]: YAML file: config\config.yaml loaded successfully
[2025-10-30 11:47:24,214: INFO: common]: YAML file: params.yaml loaded successfully
[2025-10-30 11:47:24,215: INFO: common]: YAML file: schema.yaml loaded successfully
[2025-10-30 11:47:24,215: INFO: common]: created directory at: artifacts
[2025-10-30 11:47:24,215: INFO: common]: created directory at: artifacts/data_ingestion
[2025-10-30 11:47:24,217: INFO: data_ingestion]: Extracted zip file artifacts/data_ingestion/data.zip to artifacts/data_ingestion
[2025-10-30 11:47:24,217: INFO: main]: >>>>>> Stage Data Ingestion Stage completed <<<<<<


[2025-10-30 11:47:24,218: INFO: main]: >>>>>> Stage Data Validation Stage started <<<<<<
[2025-10-30 11:47:24,219: INFO: common]: YAML file: config\config.yaml loaded successfully
[2025-10-30 11:47:24,219: INFO: common]: YAML file: params.yaml loaded successfully
[2025-10-30 11:47:24,220: INFO: common]: YAML file: schema.yaml loaded successfully
[2025-10-30 11:47:24,221: INFO: common]: created directory at: artifacts
[2025-10-30 11:47:24,221: INFO: common]: created directory at: artifacts/data_validation
[2025-10-30 11:47:24,237: INFO: data_validation_pipline]: Data validation status: False
[2025-10-30 11:47:24,237: INFO: main]: >>>>>> Stage Data Validation Stage completed <<<<<<


[2025-10-30 11:47:24,237: INFO: main]: >>>>>> Stage Data Transformation Stage started <<<<<<
[2025-10-30 11:47:24,238: ERROR: data_transformation_pipline]: Your Data scheme is not valid
Traceback (most recent call last):
  File "D:\Projects\dsproject\src\datascience\pipeline\data_transformation_pipline.py", line 30, in initiate_data_transformation
    raise Exception("Your Data scheme is not valid")
Exception: Your Data scheme is not valid
[2025-10-30 11:47:24,239: ERROR: main]: Your Data scheme is not valid
Traceback (most recent call last):
  File "D:\Projects\dsproject\main.py", line 34, in <module>
    data_transformation.initiate_data_transformation()
    ~~~~~~~~~~~~~~~~~~~~~~~~~~~~~~~~~~~~~~~~~~~~~~~~^^
  File "D:\Projects\dsproject\src\datascience\pipeline\data_transformation_pipline.py", line 33, in initiate_data_transformation
    raise e
  File "D:\Projects\dsproject\src\datascience\pipeline\data_transformation_pipline.py", line 30, in initiate_data_transformation
    raise Exception("Your Data scheme is not valid")
Exception: Your Data scheme is not valid
[2025-10-30 11:53:48,929: INFO: main]: Datascience package initialized.
[2025-10-30 11:53:49,956: INFO: main]: >>>>>> Stage Data Ingestion Stage started <<<<<<
[2025-10-30 11:53:49,958: INFO: common]: YAML file: config\config.yaml loaded successfully
[2025-10-30 11:53:49,958: INFO: common]: YAML file: params.yaml loaded successfully
[2025-10-30 11:53:49,959: INFO: common]: YAML file: schema.yaml loaded successfully
[2025-10-30 11:53:49,959: INFO: common]: created directory at: artifacts
[2025-10-30 11:53:49,960: INFO: common]: created directory at: artifacts/data_ingestion
[2025-10-30 11:53:49,961: INFO: data_ingestion]: Extracted zip file artifacts/data_ingestion/data.zip to artifacts/data_ingestion
[2025-10-30 11:53:49,962: INFO: main]: >>>>>> Stage Data Ingestion Stage completed <<<<<<


[2025-10-30 11:53:49,962: INFO: main]: >>>>>> Stage Data Validation Stage started <<<<<<
[2025-10-30 11:53:49,963: INFO: common]: YAML file: config\config.yaml loaded successfully
[2025-10-30 11:53:49,963: INFO: common]: YAML file: params.yaml loaded successfully
[2025-10-30 11:53:49,964: INFO: common]: YAML file: schema.yaml loaded successfully
[2025-10-30 11:53:49,965: INFO: common]: created directory at: artifacts
[2025-10-30 11:53:49,965: INFO: common]: created directory at: artifacts/data_validation
[2025-10-30 11:53:49,981: INFO: data_validation_pipline]: Data validation status: False
[2025-10-30 11:53:49,981: INFO: main]: >>>>>> Stage Data Validation Stage completed <<<<<<


[2025-10-30 11:53:49,981: INFO: main]: >>>>>> Stage Data Transformation Stage started <<<<<<
[2025-10-30 11:53:49,982: ERROR: data_transformation_pipline]: Your Data scheme is not valid
Traceback (most recent call last):
  File "D:\Projects\dsproject\src\datascience\pipeline\data_transformation_pipline.py", line 30, in initiate_data_transformation
    raise Exception("Your Data scheme is not valid")
Exception: Your Data scheme is not valid
[2025-10-30 11:53:49,983: ERROR: main]: Your Data scheme is not valid
Traceback (most recent call last):
  File "D:\Projects\dsproject\main.py", line 34, in <module>
    data_transformation.initiate_data_transformation()
    ~~~~~~~~~~~~~~~~~~~~~~~~~~~~~~~~~~~~~~~~~~~~~~~~^^
  File "D:\Projects\dsproject\src\datascience\pipeline\data_transformation_pipline.py", line 33, in initiate_data_transformation
    raise e
  File "D:\Projects\dsproject\src\datascience\pipeline\data_transformation_pipline.py", line 30, in initiate_data_transformation
    raise Exception("Your Data scheme is not valid")
Exception: Your Data scheme is not valid
[2025-10-30 11:54:22,307: INFO: main]: Datascience package initialized.
[2025-10-30 11:54:23,325: INFO: main]: >>>>>> Stage Data Ingestion Stage started <<<<<<
[2025-10-30 11:54:23,327: INFO: common]: YAML file: config\config.yaml loaded successfully
[2025-10-30 11:54:23,327: INFO: common]: YAML file: params.yaml loaded successfully
[2025-10-30 11:54:23,328: INFO: common]: YAML file: schema.yaml loaded successfully
[2025-10-30 11:54:23,329: INFO: common]: created directory at: artifacts
[2025-10-30 11:54:23,329: INFO: common]: created directory at: artifacts/data_ingestion
[2025-10-30 11:54:23,331: INFO: data_ingestion]: Extracted zip file artifacts/data_ingestion/data.zip to artifacts/data_ingestion
[2025-10-30 11:54:23,331: INFO: main]: >>>>>> Stage Data Ingestion Stage completed <<<<<<


[2025-10-30 11:54:23,331: INFO: main]: >>>>>> Stage Data Validation Stage started <<<<<<
[2025-10-30 11:54:23,332: INFO: common]: YAML file: config\config.yaml loaded successfully
[2025-10-30 11:54:23,333: INFO: common]: YAML file: params.yaml loaded successfully
[2025-10-30 11:54:23,334: INFO: common]: YAML file: schema.yaml loaded successfully
[2025-10-30 11:54:23,334: INFO: common]: created directory at: artifacts
[2025-10-30 11:54:23,334: INFO: common]: created directory at: artifacts/data_validation
[2025-10-30 11:54:23,347: INFO: data_validation_pipline]: Data validation status: False
[2025-10-30 11:54:23,347: INFO: main]: >>>>>> Stage Data Validation Stage completed <<<<<<


[2025-10-30 11:54:23,347: INFO: main]: >>>>>> Stage Data Transformation Stage started <<<<<<
[2025-10-30 11:54:23,348: ERROR: data_transformation_pipline]: Your Data scheme is not valid
Traceback (most recent call last):
  File "D:\Projects\dsproject\src\datascience\pipeline\data_transformation_pipline.py", line 30, in initiate_data_transformation
    raise Exception("Your Data scheme is not valid")
Exception: Your Data scheme is not valid
[2025-10-30 11:54:23,349: ERROR: main]: Your Data scheme is not valid
Traceback (most recent call last):
  File "D:\Projects\dsproject\main.py", line 34, in <module>
    data_transformation.initiate_data_transformation()
    ~~~~~~~~~~~~~~~~~~~~~~~~~~~~~~~~~~~~~~~~~~~~~~~~^^
  File "D:\Projects\dsproject\src\datascience\pipeline\data_transformation_pipline.py", line 33, in initiate_data_transformation
    raise e
  File "D:\Projects\dsproject\src\datascience\pipeline\data_transformation_pipline.py", line 30, in initiate_data_transformation
    raise Exception("Your Data scheme is not valid")
Exception: Your Data scheme is not valid
[2025-10-30 12:24:25,603: INFO: data_validation_pipline]: >>>>>> Stage Data Validation Stage started <<<<<<
[2025-10-30 12:24:25,606: INFO: common]: YAML file: config\config.yaml loaded successfully
[2025-10-30 12:24:25,613: INFO: common]: YAML file: params.yaml loaded successfully
[2025-10-30 12:24:25,614: INFO: common]: YAML file: schema.yaml loaded successfully
[2025-10-30 12:24:25,614: INFO: common]: created directory at: artifacts
[2025-10-30 12:24:25,614: INFO: common]: created directory at: artifacts/data_validation
[2025-10-30 12:24:25,619: INFO: data_validation_pipline]: Data validation status: False
[2025-10-30 12:24:25,620: INFO: data_validation_pipline]: >>>>>> Stage Data Validation Stage completed <<<<<<


[2025-10-30 12:24:40,974: INFO: data_validation_pipline]: >>>>>> Stage Data Validation Stage started <<<<<<
[2025-10-30 12:24:40,975: INFO: common]: YAML file: config\config.yaml loaded successfully
[2025-10-30 12:24:40,976: INFO: common]: YAML file: params.yaml loaded successfully
[2025-10-30 12:24:40,977: INFO: common]: YAML file: schema.yaml loaded successfully
[2025-10-30 12:24:40,977: INFO: common]: created directory at: artifacts
[2025-10-30 12:24:40,977: INFO: common]: created directory at: artifacts/data_validation
[2025-10-30 12:24:40,982: INFO: data_validation]: CSV Columns: ['fixed acidity', 'volatile acidity', 'citric acid', 'residual sugar', 'chlorides', 'free sulfur dioxide', 'total sulfur dioxide', 'density', 'pH', 'sulphates', 'alcohol', 'quality']
[2025-10-30 12:24:40,982: INFO: data_validation]: Schema Columns: ['COLUMNS', 'TARGET_COLUMN']
[2025-10-30 12:24:40,983: ERROR: data_validation]: Column 'fixed acidity' NOT found in schema!
[2025-10-30 12:24:40,983: INFO: data_validation]: Final validation status: False
[2025-10-30 12:24:40,983: INFO: data_validation_pipline]: Data validation status: False
[2025-10-30 12:24:40,983: INFO: data_validation_pipline]: >>>>>> Stage Data Validation Stage completed <<<<<<


[2025-10-30 12:25:03,949: INFO: data_validation_pipline]: >>>>>> Stage Data Validation Stage started <<<<<<
[2025-10-30 12:25:03,951: INFO: common]: YAML file: config\config.yaml loaded successfully
[2025-10-30 12:25:03,952: INFO: common]: YAML file: params.yaml loaded successfully
[2025-10-30 12:25:03,953: INFO: common]: YAML file: schema.yaml loaded successfully
[2025-10-30 12:25:03,953: INFO: common]: created directory at: artifacts
[2025-10-30 12:25:03,953: INFO: common]: created directory at: artifacts/data_validation
[2025-10-30 12:25:03,958: INFO: data_validation]: CSV Columns: ['fixed acidity', 'volatile acidity', 'citric acid', 'residual sugar', 'chlorides', 'free sulfur dioxide', 'total sulfur dioxide', 'density', 'pH', 'sulphates', 'alcohol', 'quality']
[2025-10-30 12:25:03,958: INFO: data_validation]: Schema Columns: ['fixed acidity', 'volatile acidity', 'citric acid', 'residual sugar', 'chlorides', 'free sulfur dioxide', 'total sulfur dioxide', 'density', 'pH', 'sulphates', 'alcohol', 'quality']
[2025-10-30 12:25:03,959: INFO: data_validation]: Column 'fixed acidity' found in schema
[2025-10-30 12:25:03,959: INFO: data_validation]: Column 'volatile acidity' found in schema
[2025-10-30 12:25:03,959: INFO: data_validation]: Column 'citric acid' found in schema
[2025-10-30 12:25:03,959: INFO: data_validation]: Column 'residual sugar' found in schema
[2025-10-30 12:25:03,959: INFO: data_validation]: Column 'chlorides' found in schema
[2025-10-30 12:25:03,959: INFO: data_validation]: Column 'free sulfur dioxide' found in schema
[2025-10-30 12:25:03,959: INFO: data_validation]: Column 'total sulfur dioxide' found in schema
[2025-10-30 12:25:03,959: INFO: data_validation]: Column 'density' found in schema
[2025-10-30 12:25:03,959: INFO: data_validation]: Column 'pH' found in schema
[2025-10-30 12:25:03,959: INFO: data_validation]: Column 'sulphates' found in schema
[2025-10-30 12:25:03,959: INFO: data_validation]: Column 'alcohol' found in schema
[2025-10-30 12:25:03,959: INFO: data_validation]: Column 'quality' found in schema
[2025-10-30 12:25:03,960: INFO: data_validation]: Final validation status: True
[2025-10-30 12:25:03,960: INFO: data_validation_pipline]: Data validation status: True
[2025-10-30 12:25:03,960: INFO: data_validation_pipline]: >>>>>> Stage Data Validation Stage completed <<<<<<


[2025-10-30 12:25:17,417: INFO: main]: Datascience package initialized.
[2025-10-30 12:25:22,933: INFO: main]: >>>>>> Stage Data Ingestion Stage started <<<<<<
[2025-10-30 12:25:22,934: INFO: common]: YAML file: config\config.yaml loaded successfully
[2025-10-30 12:25:22,935: INFO: common]: YAML file: params.yaml loaded successfully
[2025-10-30 12:25:22,936: INFO: common]: YAML file: schema.yaml loaded successfully
[2025-10-30 12:25:22,936: INFO: common]: created directory at: artifacts
[2025-10-30 12:25:22,937: INFO: common]: created directory at: artifacts/data_ingestion
[2025-10-30 12:25:22,949: INFO: data_ingestion]: Extracted zip file artifacts/data_ingestion/data.zip to artifacts/data_ingestion
[2025-10-30 12:25:22,949: INFO: main]: >>>>>> Stage Data Ingestion Stage completed <<<<<<


[2025-10-30 12:25:22,949: INFO: main]: >>>>>> Stage Data Validation Stage started <<<<<<
[2025-10-30 12:25:22,951: INFO: common]: YAML file: config\config.yaml loaded successfully
[2025-10-30 12:25:22,952: INFO: common]: YAML file: params.yaml loaded successfully
[2025-10-30 12:25:22,953: INFO: common]: YAML file: schema.yaml loaded successfully
[2025-10-30 12:25:22,953: INFO: common]: created directory at: artifacts
[2025-10-30 12:25:22,953: INFO: common]: created directory at: artifacts/data_validation
[2025-10-30 12:25:22,966: INFO: data_validation]: CSV Columns: ['fixed acidity', 'volatile acidity', 'citric acid', 'residual sugar', 'chlorides', 'free sulfur dioxide', 'total sulfur dioxide', 'density', 'pH', 'sulphates', 'alcohol', 'quality']
[2025-10-30 12:25:22,966: INFO: data_validation]: Schema Columns: ['fixed acidity', 'volatile acidity', 'citric acid', 'residual sugar', 'chlorides', 'free sulfur dioxide', 'total sulfur dioxide', 'density', 'pH', 'sulphates', 'alcohol', 'quality']
[2025-10-30 12:25:22,967: INFO: data_validation]: Column 'fixed acidity' found in schema
[2025-10-30 12:25:22,967: INFO: data_validation]: Column 'volatile acidity' found in schema
[2025-10-30 12:25:22,967: INFO: data_validation]: Column 'citric acid' found in schema
[2025-10-30 12:25:22,967: INFO: data_validation]: Column 'residual sugar' found in schema
[2025-10-30 12:25:22,967: INFO: data_validation]: Column 'chlorides' found in schema
[2025-10-30 12:25:22,967: INFO: data_validation]: Column 'free sulfur dioxide' found in schema
[2025-10-30 12:25:22,967: INFO: data_validation]: Column 'total sulfur dioxide' found in schema
[2025-10-30 12:25:22,967: INFO: data_validation]: Column 'density' found in schema
[2025-10-30 12:25:22,967: INFO: data_validation]: Column 'pH' found in schema
[2025-10-30 12:25:22,968: INFO: data_validation]: Column 'sulphates' found in schema
[2025-10-30 12:25:22,968: INFO: data_validation]: Column 'alcohol' found in schema
[2025-10-30 12:25:22,968: INFO: data_validation]: Column 'quality' found in schema
[2025-10-30 12:25:22,968: INFO: data_validation]: Final validation status: True
[2025-10-30 12:25:22,969: INFO: data_validation_pipline]: Data validation status: True
[2025-10-30 12:25:22,969: INFO: main]: >>>>>> Stage Data Validation Stage completed <<<<<<


[2025-10-30 12:25:22,969: INFO: main]: >>>>>> Stage Data Transformation Stage started <<<<<<
[2025-10-30 12:25:22,971: INFO: common]: YAML file: config\config.yaml loaded successfully
[2025-10-30 12:25:22,972: INFO: common]: YAML file: params.yaml loaded successfully
[2025-10-30 12:25:22,973: INFO: common]: YAML file: schema.yaml loaded successfully
[2025-10-30 12:25:22,973: INFO: common]: created directory at: artifacts
[2025-10-30 12:25:22,973: INFO: common]: created directory at: artifacts/data_transformation
[2025-10-30 12:25:23,003: INFO: data_transformation]: Splited data into training and test sets
[2025-10-30 12:25:23,003: INFO: data_transformation]: (1199, 12)
[2025-10-30 12:25:23,003: INFO: data_transformation]: (400, 12)
[2025-10-30 12:25:23,004: INFO: main]: >>>>>> Stage Data Transformation Stage completed <<<<<<


